<?xml version="1.0"?>

<robot name="rotor2" xmlns:xacro="http://ros.org/wiki/xacro">
  <xacro:include filename="$(find rotor_description)/urdf/camera.xacro" />
  <xacro:include filename="$(find rotor_description)/urdf/common.xacro" />

  <!-- Properties -->
  <xacro:property name="namespace" value="$(arg namespace)" />
  
  <link name="${namespace}/base_link">
    <visual>
      <origin rpy="0 0 0" xyz="0 0 0.05"/>
      <geometry>
        <cylinder length="0.1" radius="0.5"/>
      </geometry>
      <xacro:material_black/>
    </visual>
    <xacro:cylinder_inertial_with_origin
      radius="0.01"
      length="0.01"
      mass="0.001">
      <origin xyz="0 0 0" rpy="0 0 0" />
    </xacro:cylinder_inertial_with_origin>
  </link>

  <joint name="${namespace}/pillar_joint" type="revolute">
    <axis xyz="0 0 1"/>
    <limit lower="${-pi/3}" upper="${pi/3}" effort="1.2" velocity="6.0"/>
    <origin xyz="0 0 0.1" rpy="0.0 0.0 0.0"/>
    <parent link="${namespace}/base_link"/>
    <child link="${namespace}/pillar_link"/>
  </joint>

  <link name="${namespace}/pillar_link">
    <visual>
      <origin rpy="0 0 0" xyz="0 0 0.5"/>
      <geometry>
        <cylinder length="1" radius="0.3"/>
      </geometry>
      <xacro:material_white/>
    </visual>
    <visual>
      <origin rpy="0 0 0" xyz="0 0 1.2"/>
      <geometry>
        <box size="0.5 0.6 0.4"/>
      </geometry>
      <xacro:material_white/>
    </visual>
    <xacro:cylinder_inertial_with_origin
      radius="0.01"
      length="0.01"
      mass="0.001">
      <origin xyz="0 0 0" rpy="0 0 0" />
    </xacro:cylinder_inertial_with_origin>
  </link>
  
  <joint name="${namespace}/load_joint" type="revolute">
    <axis xyz="0 1 0"/>
    <limit lower="${-pi/4}" upper="${pi/4}" effort="1.2" velocity="6.0"/>
    <origin xyz="0 0 1.3" rpy="0.0 0.0 0.0"/>
    <parent link="${namespace}/pillar_link"/>
    <child link="${namespace}/load_link"/>
  </joint>

  <link name="${namespace}/load_link">
    <visual>
      <origin rpy="0 ${pi/2} 0" xyz="0 0.55 0"/>
      <geometry>
        <cylinder length="0.8" radius="0.25"/>
      </geometry>
      <xacro:material_grey/>
    </visual>
    <visual>
      <origin rpy="0 ${pi/2} 0" xyz="0 -0.55 0"/>
      <geometry>
        <cylinder length="0.8" radius="0.25"/>
      </geometry>
      <xacro:material_grey/>
    </visual>
    <xacro:cylinder_inertial_with_origin
      radius="0.01"
      length="0.01"
      mass="0.001">
      <origin xyz="0 0 0" rpy="0 0 0" />
    </xacro:cylinder_inertial_with_origin>
  </link>
  
  <joint name="${namespace}/laser_joint" type="fixed">
    <origin xyz="0.4 -0.55 0" rpy="0 0 0" />
    <parent link="${namespace}/load_link" />
    <child link="${namespace}/laser_link" />
  </joint>
  
  <link name="${namespace}/laser_link">
    <visual>
      <origin xyz="0 0 0" rpy="0 ${pi/2} 0" />
      <geometry>
        <cylinder length="0.008" radius="0.2"/>
      </geometry>
      <xacro:material_red/>
    </visual>
  </link>

  <xacro:camera_macro
    namespace="fixed_camera"
    parent_link="${namespace}/load_link"
    robot_namespace="/"
    camera_name="camera"
    image_topic_name="image_raw"
    camera_info_topic_name="camera_info"
    frame_rate="30"
    horizontal_fov="0.3"
    image_width="640"
    image_height="480"
    image_format="B8G8R8"
    min_distance="0.72"
    max_distance="100"
    noise_mean="0.01"
    noise_stddev="0.007"
    enable_visual="false"
    k1="0"
    k2="0"
    k3="0"
    p1="0"
    p2="0"
    cx="0.5"
    cy="0.5">
    <origin xyz="0.4 0.55 0" rpy="0 0 0" />
    <visual>
      <origin xyz="0 0 0" rpy="0 0 0" />
      <geometry>
        <box size="0.008 0.2 0.12"/>
      </geometry>
      <xacro:material_orange/>
    </visual>
    <material>Gazebo/Orange</material>
  </xacro:camera_macro>

  <xacro:if value="$(arg is_kinematic)">
    <gazebo reference="${namespace}/load_link">
      <kinematic>true</kinematic>
    </gazebo>
  </xacro:if>

  <gazebo reference="${namespace}/base_link">
    <material>Gazebo/Black</material>
  </gazebo>
  <gazebo reference="${namespace}/pillar_link">
    <material>Gazebo/Grey</material>
  </gazebo>
  <gazebo reference="${namespace}/load_link">
    <material>Gazebo/White</material>
  </gazebo>
  <gazebo reference="${namespace}/laser_link">
    <material>Gazebo/Red</material>
  </gazebo>
</robot>
